Workbook

Sheet READ ME FIRST
A1: Remax Forge & Fittings - city pages for Andhra Pradesh and Arunachal Pradesh: strategy and developer build pack
A2: remaxforge.com · prepared by errorr.in · research 27 Sep 2026 · workbook 28 Sep 2026
A4: STANDING RULE - FORMS ONLY: no visible phone number, no tel: link, no WhatsApp link or widget, and no telephone property in schema - on any page, image, video or email signature. Every lead comes through a form.
A6: Where things stand (live formulas)
B7: Impressions, all 10 URLs (GSC, about 5.5 months) | C7: ='1. Decision Summary'!$G$18 -> 175 | D7: Tab 1. City pages are a small lever.
B8: Clicks, same period | C8: ='1. Decision Summary'!$J$18 -> 5 | D8: Tab 1.
B9: Impressions per month | C9: ='1. Decision Summary'!$G$19 -> 31.818182 | D9: Tab 1.
B10: Decision for Naharlagun, Pasighat, Tawang, Ziro | C10: ='1. Decision Summary'!$C$5 -> Option A (recommended) | D10: Change it in tab 1, cell C5.
B11: Pages READY to publish | C11: =COUNTIF('6. On-Page Specs'!$Z$5:$Z$13,"READY")&" of "&ROWS('6. On-Page Specs'!$Z$5:$Z$13) -> 0 of 9 | D11: Tab 6 column Z. A page goes live only when it says READY.
B12: Page sections still holding a [CLIENT], [CONFIRM] or [DEV] marker | C12: =SUM('6. On-Page Specs'!$Q$5:$Q$13) -> 118 | D12: Counted per page in tab 6 column Q - they clear as tab 15 is filled.
B13: Client inputs still missing | C13: ='15. Client Inputs'!$C$4 -> 40 of 40 | D13: Tab 15.
B14: ...of which block publishing | C14: ='15. Client Inputs'!$C$5 -> 28 | D14: Tab 15.
B15: Tickets done | C15: ='16. Tests & Rollout'!$C$25 -> 0 of 19 | D15: Tab 16.
B16: P0 tickets still open | C16: ='16. Tests & Rollout'!$C$26 -> 4 | D16: Tab 16 - nothing new publishes while C-01 and C-02 are open.
B17: Photos live | C17: ='13. Media Plan'!$I$21 -> 0 of 15 | D17: Tab 13.
B18: Claims verified | C18: ='17. Sources'!$C$68 -> 0 of 20 | D18: Tab 17 section D.
A20: What this workbook decides
A21: 1 | B21: Rebuild 6 city pages on one template with genuinely local content: Visakhapatnam, Vijayawada, Guntur, Nellore, Kurnool, and Itanagar & Naharlagun.
A22: 2 | B22: Merge the 4 smallest towns (Option A): Naharlagun into /itanagar/; Pasighat, Tawang and Ziro into the Arunachal Pradesh hub - their keywords stay covered.
A23: 3 | B23: Add /market-area/ plus two state hubs, so state-level searches land on a hub and every city page has a parent.
A24: 4 | B24: Capture leads through forms only: a 2-step quote form in the hero, a full RFQ at #rfq, a gated chart, and hidden fields that tag each lead with its city.
A25: 5 | B25: ="Keep perspective: the 10 URLs earned "&TEXT('1. Decision Summary'!$G$18,"0")&" impressions and "&TEXT('1. Decision Summary'!$J$18,"0")&" clicks in about "&TEXT('1. Decision Summary'!$C$4,"0.0")&" months. The biggest lead lever is still the 53 flange product pages, only 2 of them indexed (daily log A-64) - ship C-01 and C-02 first." -> Keep perspective: the 10 URLs earned 175 impressions and 5 clicks in about 5.5 months. The biggest lead lever is still the 53 flange product pages, only 2 of them indexed (daily log A-64) - ship C-01 and C-02 first.
A27: Order of work
A28: 1 | B28: Client: choose Option A or B (tab 1, cell C5) and fill the yellow cells in tab 15 - blocking ones first.
A29: 2 | B29: Developer: ship DL, C-00, C-01 and C-02 in tab 16 before touching any city page.
A30: 3 | B30: Client: one factory shoot and five short videos (tab 13).
A31: 4 | B31: Developer: build the template once (tab 7), then /market-area/ and the hubs, then the P1 city pages - copy from tabs 8, 8b and 9, forms from tab 10, schema from tab 11, links, 301s and sitemap from tab 12.
A32: 5 | B32: Publish a page only when tab 6 column Z says READY; run the QA script (tab 16 section B) after every deploy.
A33: 6 | B33: Request indexing in the tab 12 order; review at W6 and W10 against the KPIs in tab 16.
A35: Tab guide (click a tab name to jump to it)
B36: Tab | C36: What is in it | E36: Who uses it
B37: 1. Decision Summary | C37: GSC data for the 10 URLs, the decision per URL, and the Option A / B switch | E37: Akshat, client
B38: 2. SERP Benchmark | C38: The 20 searches: who ranks, why, and how Remax outranks them | E38: Akshat
B39: 3. Competitor Patterns | C39: The page patterns that rank and their weaknesses | E39: Akshat
B40: 4. Viraj & Sagar Benchmark | C40: What to copy from the two benchmark sites - and what not to | E40: Akshat, writer
B41: 5. Keyword Map | C41: Every keyword mapped to one URL and one place on the page | E41: Akshat, writer
B42: 6. On-Page Specs | C42: Titles, metas, H1s, word floors, links, schema - and the READY gate | E42: Developer, Akshat
B43: 7. Page Template (Dev) | C43: The 14-section template, built once | E43: Developer
B44: 8. City Content (Paste) | C44: Paste-ready copy per section | E44: Developer
B45: 8b. Page Tables (Paste) | C45: Local-demand and product-range tables | E45: Developer
...

Sheet 1. Decision Summary
A1: 1. Decision summary - what happens to each of the 10 URLs
A2: GSC pages export, 20 Feb - 6 Aug 2026 (master plan, sheet '12. GSC Raw Data - Pages'). Each URL shows up twice in GSC - with and without the trailing slash - which is the duplicate-URL fault C-01 fixes.
B4: GSC period covered (months): 20 Feb - 6 Aug 2026 | C4: 5.5 | D4: Blue = hardcoded assumption. Change it if the export covers a different period; the per-month figures below recalculate.
B5: Decision for Naharlagun, Pasighat, Tawang and Ziro | C5: Option A (recommended) | D5: Yellow = choose. Option A: 301 each town to the combined page. Option B: keep as mini-pages - only if the keep-if condition in tab 6 (Option B block) is true. Tabs 2, 5, 6 and 12 follow this cell.
A7: # | B7: City | C7: State | D7: Current URL | E7: Impr. (no slash) | F7: Impr. (slash) | G7: Impr. total | H7: Clicks (no slash) | I7: Clicks (slash) | J7: Clicks total | K7: Avg pos. (no slash) | L7: Avg pos. (slash) | M7: Weighted avg position | N7: Share of impressions | O7: Tier | P7: Decision | Q7: Target URL | R7: Priority | S7: Why
A8: 1 | B8: Visakhapatnam | C8: Andhra Pradesh | D8: /visakhapatnam/ | E8: 25 | F8: 30 | G8: =SUM(E8:F8) -> 55 | H8: 2 | I8: 0 | J8: =SUM(H8:I8) -> 2 | K8: 4.16 | L8: 6.37 | M8: =IFERROR((N(E8)*N(K8)+N(F8)*N(L8))/(N(E8)+N(F8)),"") -> 5.3654545 | N8: =IF($G$18=0,0,G8/$G$18) -> 0.31428571 | O8: A | P8: Rebuild | Q8: /visakhapatnam/ | R8: P1 | S8: The only contested SERP of the ten (4 templated competitor pages + directories). Biggest demand base: RINL, HPCL, ports, Pharma City, and AM/NS India's 8.2 MTPA plant at Anakapalli. Most impressions of the ten.
A9: 2 | B9: Vijayawada | C9: Andhra Pradesh | D9: /vijayawada/ | E9: 13 | F9: 4 | G9: =SUM(E9:F9) -> 17 | H9: 1 | I9: 0 | J9: =SUM(H9:I9) -> 1 | K9: 5 | L9: 6 | M9: =IFERROR((N(E9)*N(K9)+N(F9)*N(L9))/(N(E9)+N(F9)),"") -> 5.2352941 | N9: =IF($G$18=0,0,G9/$G$18) -> 0.097142857 | O9: B | P9: Rebuild | Q9: /vijayawada/ | R9: P1 | S9: Kalikund material-by-city pages and Justdial rank; no strong local page. Real demand: thermal power at Ibrahimpatnam and Amaravati capital works (World Bank + ADB US$1.6 bn committed).
A10: 3 | B10: Guntur | C10: Andhra Pradesh | D10: /guntur/ | E10: 16 | F10: 5 | G10: =SUM(E10:F10) -> 21 | H10: 0 | I10: 0 | J10: =SUM(H10:I10) -> 0 | K10: 3.75 | L10: 6.4 | M10: =IFERROR((N(E10)*N(K10)+N(F10)*N(L10))/(N(E10)+N(F10)),"") -> 4.3809524 | N10: =IF($G$18=0,0,G10/$G$18) -> 0.12 | O10: B | P10: Rebuild | Q10: /guntur/ | R10: P2 | S10: No dedicated competitor page ranks. Cold-chain ammonia plant rooms and mill boilers give a distinct, genuinely useful angle.
A11: 4 | B11: Nellore | C11: Andhra Pradesh | D11: /nellore/ | E11: 15 | F11: 6 | G11: =SUM(E11:F11) -> 21 | H11: 1 | I11: 0 | J11: =SUM(H11:I11) -> 1 | K11: 2.6 | L11: 4.83 | M11: =IFERROR((N(E11)*N(K11)+N(F11)*N(L11))/(N(E11)+N(F11)),"") -> 3.2371429 | N11: =IF($G$18=0,0,G11/$G$18) -> 0.12 | O11: B | P11: Rebuild | Q11: /nellore/ | R11: P1 | S11: BPCL's 9-12 MMTPA refinery near Ramayapatnam (6,000 acres allotted Oct 2025) will pull EPC flange demand; no dedicated supplier page ranks.
A12: 5 | B12: Kurnool | C12: Andhra Pradesh | D12: /kurnool/ | E12: 4 | F12: 4 | G12: =SUM(E12:F12) -> 8 | H12: 0 | I12: 0 | J12: =SUM(H12:I12) -> 0 | K12: 2.25 | L12: 9.75 | M12: =IFERROR((N(E12)*N(K12)+N(F12)*N(L12))/(N(E12)+N(F12)),"") -> 6 | N12: =IF($G$18=0,0,G12/$G$18) -> 0.045714286 | O12: B | P12: Rebuild | Q12: /kurnool/ | R12: P2 | S12: No dedicated competitor page (an Ahmedabad firm's Andhra Pradesh state page ranks). Greenko Pinnapuram pumped storage + lift irrigation = large-bore demand.
A13: 6 | B13: Itanagar | C13: Arunachal Pradesh | D13: /itanagar/ | E13: 8 | F13: 16 | G13: =SUM(E13:F13) -> 24 | H13: 1 | I13: 0 | J13: =SUM(H13:I13) -> 1 | K13: 2.75 | L13: 8.44 | M13: =IFERROR((N(E13)*N(K13)+N(F13)*N(L13))/(N(E13)+N(F13)),"") -> 6.5433333 | N13: =IF($G$18=0,0,G13/$G$18) -> 0.13714286 | O13: C | P13: Rebuild as 'Itanagar & Naharlagun' | Q13: /itanagar/ | R13: P3 | S13: Near-zero competition and small demand. One honest page for the Itanagar-Naharlagun capital region beats two thin ones.
A14: 7 | B14: Naharlagun | C14: Arunachal Pradesh | D14: /naharlagun/ | E14: 6 | F14: 1 | G14: =SUM(E14:F14) -> 7 | H14: 0 | I14: 0 | J14: =SUM(H14:I14) -> 0 | K14: 4.17 | L14: 4 | M14: =IFERROR((N(E14)*N(K14)+N(F14)*N(L14))/(N(E14)+N(F14)),"") -> 4.1457143 | N14: =IF($G$18=0,0,G14/$G$18) -> 0.04 | O14: D (merge) | P14: =IF(LEFT('1. Decision Summary'!$C$5,8)="Option A","301 redirect to "&Q14,"Keep as mini-page (Option B)") -> 301 redirect to /itanagar/ | Q14: =IF(LEFT('1. Decision Summary'!$C$5,8)="Option A","/itanagar/","/naharlagun/ (kept)") -> /itanagar/ | R14: P3 | S14: Twin town of Itanagar in one capital region; one page covers both honestly.
A15: 8 | B15: Pasighat | C15: Arunachal Pradesh | D15: /pasighat/ | F15: 5 | G15: =SUM(E15:F15) -> 5 | I15: 0 | J15: =SUM(H15:I15) -> 0 | L15: 8 | M15: =IFERROR((N(E15)*N(K15)+N(F15)*N(L15))/(N(E15)+N(F15)),"") -> 8 | N15: =IF($G$18=0,0,G15/$G$18) -> 0.028571429 | O15: D (merge) | P15: =IF(LEFT('1. Decision Summary'!$C$5,8)="Option A","301 redirect to "&Q15,"Keep as mini-page (Option B)") -> 301 redirect to /market-area/arunachal-pradesh/ | Q15: =IF(LEFT('1. Decision Summary'!$C$5,8)="Option A","/market-area/arunachal-pradesh/","/pasighat/ (kept)") -> /market-area/arunachal-pradesh/ | R15: P3 | S15: No buyer base to write about; SERP holds only spam pages for other places.
A16: 9 | B16: Tawang | C16: Arunachal Pradesh | D16: /tawang/ | E16: 9 | G16: =SUM(E16:F16) -> 9 | H16: 0 | J16: =SUM(H16:I16) -> 0 | K16: 5.67 | M16: =IFERROR((N(E16)*N(K16)+N(F16)*N(L16))/(N(E16)+N(F16)),"") -> 5.67 | N16: =IF($G$18=0,0,G16/$G$18) -> 0.051428571 | O16: D (merge) | P16: =IF(LEFT('1. Decision Summary'!$C$5,8)="Option A","301 redirect to "&Q16,"Keep as mini-page (Option B)") -> 301 redirect to /market-area/arunachal-pradesh/ | Q16: =IF(LEFT('1. Decision Summary'!$C$5,8)="Option A","/market-area/arunachal-pradesh/","/tawang/ (kept)") -> /market-area/arunachal-pradesh/ | R16: P3 | S16: Negligible flange demand; only one programmatic competitor page exists.
A17: 10 | B17: Ziro | C17: Arunachal Pradesh | D17: /ziro/ | E17: 8 | G17: =SUM(E17:F17) -> 8 | H17: 0 | J17: =SUM(H17:I17) -> 0 | K17: 16.5 | M17: =IFERROR((N(E17)*N(K17)+N(F17)*N(L17))/(N(E17)+N(F17)),"") -> 16.5 | N17: =IF($G$18=0,0,G17/$G$18) -> 0.045714286 | O17: D (merge) | P17: =IF(LEFT('1. Decision Summary'!$C$5,8)="Option A","301 redirect to "&Q17,"Keep as mini-page (Option B)") -> 301 redirect to /market-area/arunachal-pradesh/ | Q17: =IF(LEFT('1. Decision Summary'!$C$5,8)="Option A","/market-area/arunachal-pradesh/","/ziro/ (kept)") -> /market-area/arunachal-pradesh/ | R17: P3 | S17: Negligible demand; worst position of the ten (16.5).
B18: All 10 URLs | E18: =SUM(E8:E17) -> 104 | F18: =SUM(F8:F17) -> 71 | G18: =SUM(G8:G17) -> 175 | H18: =SUM(H8:H17) -> 5 | I18: =SUM(I8:I17) -> 0 | J18: =SUM(J8:J17) -> 5 | M18: =IFERROR((SUMPRODUCT(E8:E17,K8:K17)+SUMPRODUCT(F8:F17,L8:L17))/G18,"") -> 5.7209714 | N18: =SUM(N8:N17) -> 1
B19: Per month | G19: =G18/$C$4 -> 31.818182 | J19: =J18/$C$4 -> 0.90909091
B20: Click-through rate | J20: =IF(G18=0,0,J18/G18) -> 0.028571429
A22: What this means
B23: ="All 10 URLs together earned "&TEXT(G18,"0")&" impressions and "&TEXT(J18,"0")&" clicks in about "&TEXT(C4,"0.0")&" months - roughly "&TEXT(G19,"0")&" impressions a month. City pages are a small lever." -> All 10 URLs together earned 175 impressions and 5 clicks in about 5.5 months - roughly 32 impressions a month. City pages are a small lever.
B24: The biggest lead lever is still the flange product estate: 53 finished product pages, 2 indexed (daily log A-64). Ship C-01 (trailingSlash: true) and C-02 (strip tel:/WhatsApp) before any rebuilt city page goes live - otherwise the new pages inherit the same link fault.
B25: Outside Visakhapatnam the SERPs are weak: no dedicated competitor page ranks for Guntur, Kurnool or Itanagar, and Nellore has one product-by-city page. Page-one positions are realistic once the pages are indexed and linked - not guaranteed (tab 2).
B26: Rebuild 6 pages on one template (tab 7) with genuinely local content (tabs 8-9). Merge the 4 smallest towns (Option A) - their keywords stay covered on the target pages (tab 5).
B27: Nothing publishes while tab 6 says NOT READY: every [CLIENT] and [CONFIRM] marker must be replaced with real data from tab 15, or the sentence deleted. Never guess capabilities, prices or approvals.

Sheet 2. SERP Benchmark
A1: 2. SERP benchmark - 'flanges manufacturer in {city}' and 'flange supplier in {city}' (20 searches)
A2: Checked 27 Sep 2026 with a web-search API, not geo-located Google India - positions shift by location and device. Re-check in an incognito window set to the city, or with a rank tracker, before reporting. No Remax page appeared in any result set.
A4: # | B4: City | C4: Keyword | D4: Results seen (in order) | E4: Dedicated local competitor page? | F4: Why they rank | G4: Their weaknesses | H4: How Remax outranks them | I4: Difficulty (1 easy - 5 hard) | J4: Remax target URL
A5: 1 | B5: Visakhapatnam | C5: flanges manufacturer in Visakhapatnam | D5: 1 TradeIndia - blind flanges, Visakhapatnam category page | 2 TradeIndia - SS flanges, Visakhapatnam | 3 IndiaMART - local retailer listing | 4 Nitech Stainless - templated city page | 5 Justdial - 47 flange manufacturers | 6 Justdial - MS flange manufacturers | 7 Workwise vendor page | 8 Kalikund Steel - alloy steel flanges city page | 9 Rudra Impex - templated city page | E5: Yes (4 templated competitor pages) | F5: Directories: domain authority, huge category-by-city page grids, local listings with prices and reviews. Competitor pages: exact-match URL/title/H1, thousands of internally linked city pages, aged domains. | G5: Templated copy with city-swap errors: Nitech's Vizag page says it made its name 'in the Hyderabad market'; Rudra Impex lists carbide cutters and conveyor belts as flange types and mentions Hubli, Dhar and Chennai. No local industry, no delivery facts, no prices; phone/WhatsApp-first CTAs. | H5: Get indexed and linked first (C-01, C-03 to C-05). Then out-content them on local substance: AM/NS Anakapalli, HPCL, ports, Pharma City; coastal/sour/oxygen material guidance; delivery and document facts; price guidance; GSTIN and real factory media. Realistic target: first page below the directories. | I5: 4 | J5: /visakhapatnam/
A6: 2 | B6: Visakhapatnam | C6: flange supplier in Visakhapatnam | D6: 1 TradeIndia - SS flanges | 2 Riddhi Siddhi Metal Impex - templated city page | 3 Dolphin Rubber - flange gaskets | 4 stainlesssteelscrews.in - flange bolts | 5 Nitech Stainless | 6 Kanakbhuvan - pipe fittings city page | 7 Justdial | 8 Kalikund Steel | 9 Rudra Impex | E6: Yes (templated) | F6: Same as above; two results are intent mismatches (gaskets, bolts), a sign Google lacks good matches. | G6: Riddhi Siddhi claims EIL/IBR/ARAMCO approvals with no evidence on the page and says it covers 'more than 55 cities in Visakhapatnam'. | H6: Same page as the manufacturer query (one URL per city). Answer supplier-intent questions directly in FAQs (local stock? delivery time? documents?). | I6: 3 | J6: /visakhapatnam/
A7: 3 | B7: Vijayawada | C7: flanges manufacturer in Vijayawada | D7: 1 Nova Steel - India page listing Vijayawada | 2 Justdial - flange dealers (Mumbai sellers 'also serve Vijayawada', from Rs 110/kg) | 3-6 Kalikund Steel - SS, super duplex, Monel, Incoloy city pages | 7 AISI 4130 city page (Kalikund) | 8 Steel Pipe Sourcing (astmsteelpipes.com) city page | 9 Diamond Flanges - Kolkata homepage | E7: Yes (Kalikund material-by-city matrix) | F7: Kalikund's material x city matrix (hundreds of pages) plus locality stuffing: Kondapalli, Auto Nagar, Mangalagiri, Mallavalli, Gannavaram, Ibrahimpatnam. | G7: Unreadable keyword lists dated 2021; nothing a buyer can use. Justdial shows Mumbai sellers and a per-kg price anchor - price transparency is expected. | H7: One strong page with material H2s (MS/SS/alloy) to capture 'ss flanges vijayawada' variants, Amaravati and NTTPS content, the Class 150 vs PN16 drilling guide, and a price section. | I7: 3 | J7: /vijayawada/
A8: 4 | B8: Vijayawada | C8: flange supplier in Vijayawada | D8: 1 TradeIndia - local distributor (India Pipe & Fitting Store, Tarapet) | 2 Kiran Industries - flange bolts | 3 stainlesssteelscrews.in - flange bolts | 4 OD Engineers - puddle flange (spun template) | 5-8 Justdial - flange / blind / puddle / split flange dealers | 9 Kalikund Steel | E8: Partial | F8: Directory authority and a genuine local distributor listing; the rest fill gaps. | G8: Three intent mismatches (bolts, puddle flange spam). | H8: Same URL as above; supplier FAQ answers the 'local dealer?' question honestly. | I8: 3 | J8: /vijayawada/
A9: 5 | B9: Guntur | C9: flanges manufacturer in Guntur | D9: 1 IndiaMART - pipe fittings in Guntur | 2 Justdial - aluminium flange distributors (non-local listings) | 3 Snomi (Kolkata) - Guntur in a service list | 4-9 national 'flanges manufacturer in India' pages (Vishal Steel, Petromet, Mesta, Excel Metal, flanges.co, Diamond) | E9: No | F9: No dedicated page exists, so Google falls back to national pages and directories. | G9: Nothing Guntur-specific anywhere on page one. | H9: First indexed, well-linked Guntur page with real local substance (cold chain, agro-processing, IBR, capital region) should reach the top 3. | I9: 2 | J9: /guntur/
A10: 6 | B10: Guntur | C10: flange supplier in Guntur | D10: 1 aajjo - flange spreader tool | 2 IndiaMART directory | 3 Justdial - aluminium flange distributors | 4 Digvijay Metals - city list | 5 Justdial - CS flange dealers, Ashok Nagar (Mumbai firms listed) | 6 TradeIndia seller list | 7 Sagar Steel India page | 8 IndiaMART category | 9 Skyland Metal | E10: No | F10: Directory grids and city-name lists. | G10: Intent mismatch at #1 (a tool). | H10: Same page; answer the 'local supplier?' question in FAQ 1. | I10: 2 | J10: /guntur/
A11: 7 | B11: Nellore | C11: flanges manufacturer in Nellore | D11: 1 Nascent Fittings - blind flange, Nellore (hierarchical /city/india/andhra-pradesh/nellore/... URL) | 2-9 national pages (Bhansali Techno, Sagar Steel, Marcel Piping, Vishal Steel, Rajtilak, Excel Metal, flanges.co, Diamond) | E11: Partial (one product-by-city page) | F11: Clean hierarchical URL on Nascent; otherwise national fallbacks. | G11: Nascent's page is generic blind-flange text with the city name. | H11: Refinery-EPC angle (BPCL Ramayapatnam) plus power and port content; EPC checklist is unique on this SERP. | I11: 2 | J11: /nellore/
A12: 8 | B12: Nellore | C12: flange supplier in Nellore | D12: 1 aajjo - display flange | 2 Justdial - tank flange | 3 Justdial - ASA flange exporters | 4 Marcel Piping - city list | 5 Sagar Steel | 6 Wikipedia - Transport in Nellore | 7-8 Snomi GI/MS flange pages | 9 Vishal Steel | E12: No | F12: Nothing relevant exists; a Wikipedia transport page ranks. | G12: Page one is almost entirely off-intent. | H12: Same page; very achievable top 3 once indexed. | I12: 1 | J12: /nellore/
A13: 9 | B13: Kurnool | C13: flanges manufacturer in Kurnool | D13: 1 MH Infra Project (Ahmedabad) - 'Stainless Steel Flanges in Andhra Pradesh' state page listing districts | 2 Ambica Group - city list | 3 TradeIndia | 4-9 national pages | E13: No (a state page ranks) | F13: A STATE-level page captures the city query - evidence that a good Andhra Pradesh hub helps every AP city. | G13: MH Infra's page is a district list with generic copy. | H13: Kurnool page (pumped storage, irrigation, plate vs forged) plus the AP hub. | I13: 2 | J13: /kurnool/
A14: 10 | B14: Kurnool | C14: flange supplier in Kurnool | D14: 1 Digvijay Metals - city list | 2 Kanakbhuvan - India page | 3 TradeIndia | 4 Kanakbhuvan - Chennai page (wrong city) | 5 IndiaMART | 6 Petromet | 7 Vishal Steel | 8 stackshare 'flange supplier in dubai' (junk) | E14: No | F14: Pure fallback. | G14: A Chennai page and a junk page rank for Kurnool. | H14: Same page; top 3 achievable. | I14: 1 | J14: /kurnool/
A15: 11 | B15: Itanagar | C15: flanges manufacturer in Itanagar | D15: 1-9 national 'flanges manufacturer in India' pages only (Metalica Forging, Marcel, Vishal, Sagar, Metal Forge India, Excel Metal, flanges.co, Induskart, Diamond) | E15: No | F15: No competitor has an Itanagar page. | G15: - | H15: Remax already shows at ~2.8 in GSC; a better page keeps it there. Demand is tiny. | I15: 1 | J15: /itanagar/
A16: 12 | B16: Itanagar | C16: flange supplier in Itanagar | D16: 1 aajjo - refractory anchor | 2 Ananka | 3 TradeIndia | 4 Metalica | 5 IndiaMART | 6 Sagar Steel | 7 Timex Metals | 8 Metal Forge India | 9 Vishal Steel | E16: No | F16: Fallback only. | G16: - | H16: Same page. | I16: 1 | J16: /itanagar/
A17: 13 | B17: Naharlagun | C17: flanges manufacturer in Naharlagun | D17: 1 Meghmani Metal - 'Naharlagun' tag archive, page 6 | 2-9 national pages | E17: No | F17: Tag-archive spam. | G17: - | H17: Covered by the Itanagar & Naharlagun page (Option A). | I17: 1 | J17: =IF(LEFT('1. Decision Summary'!$C$5,8)="Option A","/itanagar/","/naharlagun/ (Option B)") -> /itanagar/
A18: 14 | B18: Naharlagun | C18: flange supplier in Naharlagun | D18: Only rfpindia.com programmatic pages for other places: Nagaon (Assam), Naha (Okinawa), Dadra & Nagar Haveli, Tiha Bargaului (Romania), Ikerasassuaq (Greenland), Susa (Nagorno-Karabakh) ... | E18: No | F18: No page exists for the town at all. | G18: The only 'competitor' is a site generating pages for every place on Earth - the pattern Google's scaled-content policy targets. | H18: Do not compete with a standalone page; Itanagar page covers it. | I18: 1 | J18: =IF(LEFT('1. Decision Summary'!$C$5,8)="Option A","/itanagar/","/naharlagun/ (Option B)") -> /itanagar/
A19: 15 | B19: Pasighat | C19: flanges manufacturer in Pasighat | D19: Noise: a 2022 Debian mailing-list spam email, an enggpro directory entry, a Korean flange maker, rfpindia pages for Passy (France), Cerro de Pasco (Peru), Pasadena (US), Pauri ... | E19: No | F19: No relevant results exist. | G19: - | H19: Arunachal hub section (Option A). | I19: 1 | J19: =IF(LEFT('1. Decision Summary'!$C$5,8)="Option A","/market-area/arunachal-pradesh/","/pasighat/ (Option B)") -> /market-area/arunachal-pradesh/
A20: 16 | B20: Pasighat | C20: flange supplier in Pasighat | D20: rfpindia pages for Panipat, Passy, Cerro de Pasco, Pauri, Pasadena (MD and TX), Pachmarhi, Paucarpata, Passirana di Rho | E20: No | F20: No relevant results exist. | G20: - | H20: Arunachal hub section. | I20: 1 | J20: =IF(LEFT('1. Decision Summary'!$C$5,8)="Option A","/market-area/arunachal-pradesh/","/pasighat/ (Option B)") -> /market-area/arunachal-pradesh/
A21: 17 | B21: Tawang | C21: flanges manufacturer in Tawang | D21: enggpro directory, Debian spam email, Product Hunt profile, rfpindia 'Pipe Fittings Supplier in Tawang' (the only Tawang-named page), enggpro blog, rfpindia pages for Tungkang, Taywarah, Taungdwingyi, Tavush, Plateaux (Togo) | E21: One programmatic page (rfpindia) | F21: No relevant results exist. | G21: - | H21: Arunachal hub section with the cold-service and winter-logistics angle. | I21: 1 | J21: =IF(LEFT('1. Decision Summary'!$C$5,8)="Option A","/market-area/arunachal-pradesh/","/tawang/ (Option B)") -> /market-area/arunachal-pradesh/
A22: 18 | B22: Tawang | C22: flange supplier in Tawang | D22: 1 rfpindia - Pipe Fittings Supplier in Tawang | 2-10 rfpindia pages for Titwan, Tungkang, Keelung, Taywarah, Tutume, Tov (Mongolia), Takaev, Tabora ... | E22: One programmatic page | F22: - | G22: - | H22: Arunachal hub section. | I22: 1 | J22: =IF(LEFT('1. Decision Summary'!$C$5,8)="Option A","/market-area/arunachal-pradesh/","/tawang/ (Option B)") -> /market-area/arunachal-pradesh/
A23: 19 | B23: Ziro | C23: flanges manufacturer in Ziro | D23: Debian spam email, enggpro directory, a Chinese flange maker (Jiangyin Zeli), rfpindia pages for Ozoir-la-Ferriere, Mashonaland East, Kushiro, Zaranj, Isiro, Zareh Sharan, a Viraj listing on expometals | E23: No | F23: - | G23: - | H23: Arunachal hub section. | I23: 1 | J23: =IF(LEFT('1. Decision Summary'!$C$5,8)="Option A","/market-area/arunachal-pradesh/","/ziro/ (Option B)") -> /market-area/arunachal-pradesh/
A24: 20 | B24: Ziro | C24: flange supplier in Ziro | D24: rfpindia pages only: Ozoir-la-Ferriere, Mashonaland East, Risch-Rotkreuz, Matabeleland North, Zarqa, Isiro, Zadar, Kushiro, Zaranj, Zareh Sharan | E24: No | F24: - | G24: - | H24: Arunachal hub section. | I24: 1 | J24: =IF(LEFT('1. Decision Summary'!$C$5,8)="Option A","/market-area/arunachal-pradesh/","/ziro/ (Option B)") -> /market-area/arunachal-pradesh/
B26: Keywords at difficulty 1-2 | C26: =COUNTIF(I5:I24,"<=2")&" of "&COUNT(I5:I24) -> 16 of 20
B27: Average difficulty | C27: =AVERAGE(I5:I24) -> 1.65
B28: Difficulty scale | C28: 1 = no relevant competitor page; 3 = templated/national pages only; 5 = strong dedicated local pages + directories. Judged from the result sets above, not from a tool score.

Sheet 3. Competitor Patterns
A1: 3. Competitor patterns - who ranks for these city keywords, why, and how Remax beats each pattern
A2: Patterns seen across the 20 result sets in tab 2. The lesson: every ranking page wins on exact-match structure and internal linking, not on content quality - Remax can match the structure and beat the content.
A4: # | B4: Competitor / pattern | C4: Page type | D4: Why it ranks | E4: Weakness | F4: How Remax beats it
A5: 1 | B5: IndiaMART / TradeIndia / Justdial / aajjo / Workwise | C5: Directory / marketplace | D5: Domain authority; category x city page grids; local listings with prices, ratings and reviews. | E5: Generic; the buyer must call several sellers; many listings are Mumbai firms 'also serving' the city. Listings expose phone numbers. | F5: Do not fight on authority. Win the dedicated-page slot beneath them and convert better (written quotes, prices, documents). Listing there conflicts with the forms-only rule - client's call.
A6: 2 | B6: Kalikund Steel (kalikundsteel.com/city/...) | C6: Material x city matrix (2021) | D6: Hundreds of exact-match pages, heavy internal linking, locality names stuffed into keyword lists. | E6: Unreadable keyword strings; no buyer information; old. | F6: Capture material variants with H2 sections on ONE city page (never separate city x material pages - avoids the thin-page trap).
A7: 3 | B7: Nitech Stainless | C7: Templated city pages | D7: Exact-match title and URL; site-wide city links. | E7: Template leak: the Visakhapatnam page says the firm made its name 'in the Hyderabad market'. | F7: Local facts only a real supplier would know (sites, routes, documents).
A8: 4 | B8: Rudra Impex | C8: Spun template | D8: Exact-match URLs by city and product. | E8: Lists carbide cutters, conveyor belts and felt sheets as 'types of flange'; names Hubli, Dhar and Chennai on the Vizag page; claims to be the 'largest flange manufacturer in Visakhapatnam'. | F8: Accuracy and plain honesty (we ship from Mumbai).
A9: 5 | B9: Riddhi Siddhi Metal Impex | C9: Templated city pages | D9: Approval claims (EIL, IBR, ARAMCO) and exact-match titles. | E9: No evidence of approvals on the page; 'more than 55 cities in Visakhapatnam'. | F9: State only verifiable credentials: GSTIN with portal link, real certificates, real photos.
A10: 6 | B10: Kanakbhuvan Industries | C10: City pages (pipe fittings / flanges) | D10: Volume of city pages. | E10: Its Chennai page ranks for a Kurnool query - the SERP is that thin. | F10: Dedicated Kurnool page wins by default once indexed.
A11: 7 | B11: Steel Pipe Sourcing (astmsteelpipes.com) | C11: City directory pages | D11: Exact-match URL /vijayawada/flanges.htm. | E11: Generic 'stainless steel products in Vijayawada' copy. | F11: Specific Vijayawada content (NTTPS, Kondapalli, Amaravati drilling standards).
A12: 8 | B12: Nascent Fittings | C12: Hierarchical product x city pages | D12: Clean URL tree /city/india/{state}/{city}/{category}/{product}. | E12: Thin generic text per product with a city name. | F12: Copy the hierarchy idea (state hub -> city), not the thin product x city pages.
A13: 9 | B13: MH Infra Project (Ahmedabad) | C13: State-level page | D13: One Andhra Pradesh page listing all districts ranks for 'flanges manufacturer in Kurnool'. | E13: Generic. | F13: Proof that a strong state hub earns city long-tail: build /market-area/andhra-pradesh/.
A14: 10 | B14: rfpindia.com | C14: Programmatic pages for every place on Earth | D14: Sheer volume; the only results for Naharlagun, Pasighat, Tawang and Ziro queries. | E14: Pages for Greenland, Okinawa and Nagorno-Karabakh villages - textbook scaled-content abuse. | F14: Cautionary example: do not keep near-empty town pages; consolidate them.
A15: 11 | B15: National 'flanges manufacturer in India' pages (Vishal Steel, Marcel Piping, Sagar Steel, Metalica, Excel Metal ...) | C15: Fallback national pages | D15: Rank for small-city queries only because no city page exists; long city-name lists in the copy. | E15: Nothing city-specific. | F15: A genuine city page beats them on relevance once it is indexed.

Sheet 4. Viraj & Sagar Benchmark
A1: 4. Viraj & Sagar Steel benchmark - what to copy, what to skip
A2: Viraj = content depth (capability disclosure). Sagar = educational tables. Remax adopts the depth and the education, fixes the errors, and keeps forms-only lead capture.
A4: # | B4: Element | C4: Viraj (viraj.com/stainless-steel-flanges/) | D4: Sagar Steel (sagarsteel.net/flanges-manufacturer-india/) | E4: What Remax should publish | F4: Where | G4: Adopt?
A5: 1 | B5: Capability disclosure | C5: Integrated forge shop: cutting, forging, ring rolling, CNC lathes, CNC drilling, high-capacity forging press, mobile manipulator; in-house heat treatment and laboratory. | D5: Generic claims ('best state of technology'). | E5: Machine list with photos: forging press or hammer (tonnage), CNC lathes (count, max swing), drilling/VMC, heat-treatment furnace, testing equipment - only what exists. | F5: /manufacturing/ page (new or existing) + 120-word summary on city pages | G5: YES
A6: 2 | B6: Capacity & size range | C6: 18,000 MT per annum; stainless flanges from 1/2" to 40". | D6: 1/2" (15 NB) to 48" (1200 NB), DN10-DN5000. | E6: Monthly capacity and size range per flange type and standard. | F6: Spec tables on product pages; one line on city pages | G6: YES
A7: 3 | B7: Testing list | C7: PMI spectrometer, ultrasonic, tensile, impact (room temp and sub-zero), hardness, microscopy, IGC, dye penetrant. | D7: 'Strict quality testing'. | E7: Honest split between in-house tests and outsourced/TPI tests; certificate type (EN 10204 3.1/3.2). | F7: Quality module (shared) + FAQ | G7: YES
A8: 4 | B8: Approvals & certificates | C8: More than 100 approvals and certifications. | D8: ISO 9001:2008 (a withdrawn edition). | E8: Only real, current certificates. If there are none yet, show GSTIN + portal link and real factory media instead of invented badges. | F8: Trust strip | G8: YES
A9: 5 | B9: Product-type explanations | C9: Accurate engineering descriptions of each flange type. | D9: Short, generic. | E9: Already done: Remax product pages run 6,500-7,800 words. Link to them; do not repeat on city pages. | F9: Product pages | G9: no
A10: 6 | B10: Specification table | C10: - | D10: Types, classes, sizes, facings, grades in one table. | E10: Same format, correct data, on product/material pages; a short filtered version on each city page (tab 8b). | F10: Product pages / city pages | G10: verify
A11: 7 | B11: Chemistry & mechanical tables | C11: - | D11: Present but wrong: tensile and yield columns are swapped on all 7 rows (e.g. F11 shown as tensile 205 / yield 415; ASTM A182 F11 Class 1 is tensile >= 415 MPa, yield >= 205 MPa); F12 and F22 chromium shown as 4-6% (F12 is 0.80-1.25%, F22 is 2.00-2.50%); pipe specs A335, A691 and SA 790 listed as flange grades. | E11: Use tab 14 values, cite the ASTM edition, never copy competitor tables. | F11: Material pages | G11: verify
A12: 8 | B12: Commercial terms | C12: - | D12: Payment modes (LC, TT, cheque), packaging, port of dispatch (Mumbai / Kalamboli), GST rate. | E12: Payment terms, packaging, documents, dispatch point and per-city transit time. | F12: City pages - delivery section | G12: YES
A13: 9 | B13: Supply record by city | C13: - | D13: 'Product supplied x city' table. | E13: Only real past supplies, anonymised (e.g. 'Class 300 weld neck flanges for a Vizag refinery contractor, 2025'). Never invent. | F13: City pages (optional block) | G13: YES (real only)
A14: 10 | B14: FAQs | C14: 4 generic FAQs with brand plugs. | D14: None on the flange page. | E14: 6-8 city-specific FAQs that answer buyer questions (tab 9). | F14: City pages | G14: no
A15: 11 | B15: Catalogue / gated download | C15: PDF catalogues plus a 'Download PDF' form modal that captures details. | D15: Size-chart page. | E15: Gated flange weight & dimension chart PDF (email capture) and catalogue. | F15: Tab 10 (Form C) | G15: YES (PDF)
A16: 12 | B16: Real imagery | C16: Red-hot forging shots, product galleries. | D16: Warehouse stock photos. | E16: Factory photos and videos (incoming) - different ones per city page. | F16: Tab 13 | G16: YES
... A18: 14 | B18: Location pages | C18: None. | D18: 'Cities we supply' lists and many thin city pages. | E18: Fewer, deeper city pages + state hubs; merge towns with no buyers. | F18: Tabs 1 and 12 | G18: no
A20: Do not copy
A21: 1 | B21: WhatsApp and tel: CTAs (Sagar) - conflicts with the forms-only rule.
A22: 2 | B22: Math captcha on the form (Sagar) - adds friction; use an invisible check (Turnstile or reCAPTCHA v3) plus a honeypot (tab 10).
A23: 3 | B23: Sagar's mechanical and chemical tables - they contain errors (tensile and yield swapped, wrong chromium for F12/F22, pipe specs listed as flange grades). See tab 14 before publishing any table.
A24: 4 | B24: Outdated certification claims - Sagar still cites ISO 9001:2008, an edition replaced by ISO 9001:2015 (2008 certificates lapsed in September 2018). Remax shows only current, real certificates.
A25: 5 | B25: Unverifiable scale claims ('largest', 'more than 55 cities in Visakhapatnam') seen on competitor pages - state facts the client can prove.

Sheet 5. Keyword Map
A1: 5. Keyword map - every keyword points to ONE URL per city (no separate manufacturer / supplier / material pages)
A2: No volume column on purpose: the GSC export shows zero city-level queries for these pages in about 5.5 months, and third-party volume estimates at city level are unreliable. Treat every row as low-volume, high-intent.
A4: # | B4: Page | C4: Keyword | D4: Type | E4: Intent | F4: Target URL | G4: Where it goes on the page | H4: Priority | I4: Note
A5: 1 | B5: Visakhapatnam | C5: flange supplier in visakhapatnam | D5: Primary | E5: Commercial - find a supplier | F5: /visakhapatnam/ | G5: Title (front), H1, FAQ 1 | H5: P1
A6: 2 | B6: Visakhapatnam | C6: flanges manufacturer in visakhapatnam | D6: Primary | E6: Commercial - find a maker | F6: /visakhapatnam/ | G6: Title (after the |), subline under H1 ('flanges manufacturer in Mumbai supplying ...'), meta description | H6: P1 | I6: Honest framing: manufacturer in Mumbai, supplier to the city.
A7: 3 | B7: Visakhapatnam | C7: flange manufacturer in visakhapatnam | D7: Variant | E7: Commercial | F7: /visakhapatnam/ | G7: Covered by the two primary placements | H7: P1 | I7: No separate URL.
A8: 4 | B8: Visakhapatnam | C8: flanges dealer in visakhapatnam | D8: Variant (dealer / stockist) | E8: Commercial - local stock | F8: /visakhapatnam/ | G8: FAQ 1 answers it honestly: shipped direct from Mumbai, no local dealer | H8: P1 | I8: Do not claim a local stockist.
A9: 5 | B9: Visakhapatnam | C9: ms flanges visakhapatnam | D9: Material | E9: Commercial | F9: /visakhapatnam/ | G9: Range intro ('Carbon-steel (MS) flanges in ASTM A105') + demand table | H9: P1
A10: 6 | B10: Visakhapatnam | C10: ss flanges visakhapatnam | D10: Material | E10: Commercial | F10: /visakhapatnam/ | G10: Range intro (SS 304/304L, 316/316L) + materials section | H10: P1
A11: 7 | B11: Visakhapatnam | C11: flange price visakhapatnam | D11: Price | E11: Commercial - price check | F11: /visakhapatnam/ | G11: Section 'Flange prices for Visakhapatnam delivery' | H11: P1 | I11: Needs the client's dated Rs/kg bands (tab 15) to compete with directory prices.
A12: 8 | B12: Visakhapatnam | C12: duplex flanges visakhapatnam | D12: Material (niche) | E12: Commercial | F12: /visakhapatnam/ | G12: Materials section (seawater: super duplex F53/F55 or 6Mo F44; duplex F51/F60 for splash zones) + FAQ 4 | H12: P1
A13: 9 | B13: Visakhapatnam | C13: nace flanges visakhapatnam | D13: Spec | E13: Commercial | F13: /visakhapatnam/ | G13: Materials section (sour service) + FAQ 5 + link to the sour-service product page | H13: P1
A14: 10 | B14: Visakhapatnam | C14: flanges for steel plant visakhapatnam | D14: Industry | E14: Commercial | F14: /visakhapatnam/ | G14: Demand table row 1 + FAQ 3 | H14: P1
A15: 11 | B15: Visakhapatnam | C15: flange supplier gajuwaka | D15: Local area | E15: Commercial | F15: /visakhapatnam/ | G15: Section 'Areas we deliver in and around Visakhapatnam' + demand table | H15: P1 | I15: Mention in text only - no locality pages.
A16: 12 | B16: Visakhapatnam | C16: flange supplier autonagar visakhapatnam | D16: Local area | E16: Commercial | F16: /visakhapatnam/ | G16: Section 'Areas we deliver in and around Visakhapatnam' + demand table | H16: P1 | I16: Mention in text only - no locality pages.
A17: 13 | B17: Visakhapatnam | C17: flange supplier duvvada | D17: Local area | E17: Commercial | F17: /visakhapatnam/ | G17: Section 'Areas we deliver in and around Visakhapatnam' + demand table | H17: P1 | I17: Mention in text only - no locality pages.
A18: 14 | B18: Visakhapatnam | C18: flange supplier parawada | D18: Local area | E18: Commercial | F18: /visakhapatnam/ | G18: Section 'Areas we deliver in and around Visakhapatnam' + demand table | H18: P1 | I18: Mention in text only - no locality pages.
A19: 15 | B19: Visakhapatnam | C19: flange supplier anakapalli | D19: Local area | E19: Commercial | F19: /visakhapatnam/ | G19: Section 'Areas we deliver in and around Visakhapatnam' + demand table | H19: P1 | I19: Mention in text only - no locality pages.
A20: 16 | B20: Visakhapatnam | C20: flange supplier in vizag | D20: Alt city name | E20: Commercial | F20: /visakhapatnam/ | G20: H1 '(Vizag)' + meta description | H20: P1
A21: 17 | B21: Vijayawada | C21: flange supplier in vijayawada | D21: Primary | E21: Commercial - find a supplier | F21: /vijayawada/ | G21: Title (front), H1, FAQ 1 | H21: P1
A22: 18 | B22: Vijayawada | C22: flanges manufacturer in vijayawada | D22: Primary | E22: Commercial - find a maker | F22: /vijayawada/ | G22: Title (after the |), subline under H1 ('flanges manufacturer in Mumbai supplying ...'), meta description | H22: P1 | I22: Honest framing: manufacturer in Mumbai, supplier to the city.
A23: 19 | B23: Vijayawada | C23: flange manufacturer in vijayawada | D23: Variant | E23: Commercial | F23: /vijayawada/ | G23: Covered by the two primary placements | H23: P1 | I23: No separate URL.
A24: 20 | B24: Vijayawada | C24: flanges dealer in vijayawada | D24: Variant (dealer / stockist) | E24: Commercial - local stock | F24: /vijayawada/ | G24: FAQ 1 answers it honestly: shipped direct from Mumbai, no local dealer | H24: P1 | I24: Do not claim a local stockist.
A25: 21 | B25: Vijayawada | C25: ms flanges vijayawada | D25: Material | E25: Commercial | F25: /vijayawada/ | G25: Range intro ('Carbon-steel (MS) flanges in ASTM A105') + demand table | H25: P1
A26: 22 | B26: Vijayawada | C26: ss flanges vijayawada | D26: Material | E26: Commercial | F26: /vijayawada/ | G26: Range intro (SS 304/304L, 316/316L) + materials section | H26: P1
A27: 23 | B27: Vijayawada | C27: flange price vijayawada | D27: Price | E27: Commercial - price check | F27: /vijayawada/ | G27: Section 'Pricing water-project and power-plant flanges' | H27: P1 | I27: Needs the client's dated Rs/kg bands (tab 15) to compete with directory prices.
A28: 24 | B28: Vijayawada | C28: pn16 flanges vijayawada | D28: Spec | E28: Commercial | F28: /vijayawada/ | G28: Materials section 'Class 150 or PN16?' + FAQ 3 | H28: P1
A29: 25 | B29: Vijayawada | C29: flanges for amaravati projects | D29: Industry / project | E29: Commercial | F29: /vijayawada/ | G29: Demand table (capital city construction) + FAQ 2 | H29: P1
A30: 26 | B30: Vijayawada | C30: f22 flanges vijayawada | D30: Material (niche) | E30: Commercial | F30: /vijayawada/ | G30: Materials section (power-plant steam) + FAQ 4 | H30: P1
A31: 27 | B31: Vijayawada | C31: flange supplier kondapalli | D31: Local area | E31: Commercial | F31: /vijayawada/ | G31: Section 'Areas we deliver around Vijayawada' + demand table | H31: P1 | I31: Mention in text only - no locality pages.
A32: 28 | B32: Vijayawada | C32: flange supplier ibrahimpatnam | D32: Local area | E32: Commercial | F32: /vijayawada/ | G32: Section 'Areas we deliver around Vijayawada' + demand table | H32: P1 | I32: Mention in text only - no locality pages.
A33: 29 | B33: Vijayawada | C33: flange supplier autonagar vijayawada | D33: Local area | E33: Commercial | F33: /vijayawada/ | G33: Section 'Areas we deliver around Vijayawada' + demand table | H33: P1 | I33: Mention in text only - no locality pages.
A34: 30 | B34: Vijayawada | C34: flange supplier amaravati | D34: Local area | E34: Commercial | F34: /vijayawada/ | G34: Section 'Areas we deliver around Vijayawada' + demand table | H34: P1 | I34: Mention in text only - no locality pages.
A35: 31 | B35: Vijayawada | C35: flange supplier gannavaram | D35: Local area | E35: Commercial | F35: /vijayawada/ | G35: Section 'Areas we deliver around Vijayawada' + demand table | H35: P1 | I35: Mention in text only - no locality pages.
A36: 32 | B36: Guntur | C36: flange supplier in guntur | D36: Primary | E36: Commercial - find a supplier | F36: /guntur/ | G36: Title (front), H1, FAQ 1 | H36: P2
A37: 33 | B37: Guntur | C37: flanges manufacturer in guntur | D37: Primary | E37: Commercial - find a maker | F37: /guntur/ | G37: Title (after the |), subline under H1 ('flanges manufacturer in Mumbai supplying ...'), meta description | H37: P2 | I37: Honest framing: manufacturer in Mumbai, supplier to the city.
A38: 34 | B38: Guntur | C38: flange manufacturer in guntur | D38: Variant | E38: Commercial | F38: /guntur/ | G38: Covered by the two primary placements | H38: P2 | I38: No separate URL.
A39: 35 | B39: Guntur | C39: flanges dealer in guntur | D39: Variant (dealer / stockist) | E39: Commercial - local stock | F39: /guntur/ | G39: FAQ 1 answers it honestly: shipped direct from Mumbai, no local dealer | H39: P2 | I39: Do not claim a local stockist.
A40: 36 | B40: Guntur | C40: ms flanges guntur | D40: Material | E40: Commercial | F40: /guntur/ | G40: Range intro ('Carbon-steel (MS) flanges in ASTM A105') + demand table | H40: P2
A41: 37 | B41: Guntur | C41: ss flanges guntur | D41: Material | E41: Commercial | F41: /guntur/ | G41: Range intro (SS 304/304L, 316/316L) + materials section | H41: P2
...

Sheet 6. On-Page Specs
A1: 6. On-page specs - one row per URL. A page publishes only when column Z says READY.
A2: Title <= 60 chars, meta 120-160 chars. Word floors stop thin pages - they are not targets, never pad. Word counts and open placeholders are live formulas over tabs 8, 8b and 9.
A4: Page key | B4: Page | C4: Canonical URL (absolute, slash form) | D4: Build status | E4: Priority | F4: Title tag | G4: Title chars | H4: Title check | I4: Meta description | J4: Meta chars | K4: Meta check | L4: H1 | M4: Subline under H1 | N4: Word floor (no padding) | O4: Words drafted (tabs 8+8b+9) | P4: Word check | Q4: Open placeholders | R4: Uniqueness target | S4: Internal links OUT (add these) | T4: Internal links IN (must exist at launch) | U4: Photos (tab 13) | V4: Video (tab 13) | W4: Schema (tab 11) | X4: Breadcrumb | Y4: Meta robots | Z4: Ready to publish?
A5: vizag | B5: Visakhapatnam | C5: https://remaxforge.com/visakhapatnam/ | D5: REBUILD | E5: P1 | F5: Flange Supplier in Visakhapatnam | Flanges Manufacturer | G5: =LEN(F5) -> 55 | H5: =IF(G5=0,"MISSING",IF(G5>60,"TOO LONG",IF(G5<30,"TOO SHORT","OK"))) -> OK | I5: Forged flanges for Vizag and Anakapalli steel plants, the refinery, ports and Pharma City. CS, SS, alloy and NACE grades from Mumbai. Written quotes. | J5: =LEN(I5) -> 149 | K5: =IF(J5=0,"MISSING",IF(J5>160,"TOO LONG",IF(J5<120,"SHORT","OK"))) -> OK | L5: Flange Supplier in Visakhapatnam (Vizag) | M5: Flanges manufacturer in Mumbai supplying Visakhapatnam and Anakapalli steel, refinery, port, power and pharma sites. | N5: 1400 | O5: =SUMIFS('8. City Content (Paste)'!$H$5:$H$400,'8. City Content (Paste)'!$A$5:$A$400,$A5)+SUMIFS('8b. Page Tables (Paste)'!$H$5:$H$300,'8b. Page Tables (Paste)'!$A$5:$A$300,$A5)+SUMIFS('9. FAQs (Paste)'!$F$5:$F$200,'9. FAQs (Paste)'!$A$5:$A$200,$A5) -> 1703 | P5: =IF(O5>=N5,"OK","BELOW FLOOR") -> OK | Q5: =COUNTIFS('8. City Content (Paste)'!$A$5:$A$400,$A5,'8. City Content (Paste)'!$I$5:$I$400,"<>Ready")+COUNTIFS('8b. Page Tables (Paste)'!$A$5:$A$300,$A5,'8b. Page Tables (Paste)'!$I$5:$I$300,"<>Ready")+COUNTIFS('9. FAQs (Paste)'!$A$5:$A$200,$A5,'9. FAQs (Paste)'!$G$5:$G$200,"<>Ready") -> 18 | R5: >= 65% unique 5-word shingles; max similarity to any other city page <= 0.25 | S5: Flange supply across Andhra Pradesh → /market-area/andhra-pradesh/ Nellore (refinery projects) → /nellore/ Sour-service NACE flanges → /products/flanges/sour-service-nace-flange/ Flanges for oil & gas → /industries/oil-and-gas/ Pipe flanges guide → /blogs/pipe-flanges-guide/ + 7 product-type links (tab 8b) | T5: AP hub (city section + list); /nellore/ related links; /industries/oil-and-gas/ 'Where we supply' block (optional) | U5: P03, P07, P09 | V5: V1 | W5: WebPage, BreadcrumbList, Service, FAQPage (+ sitewide Organization, WebSite, Person) | X5: Home › Areas We Supply › Andhra Pradesh › Visakhapatnam | Y5: index, follow | Z5: =IF(AND(H5="OK",K5="OK",P5="OK",Q5=0),"READY","NOT READY") -> NOT READY
A6: vijayawada | B6: Vijayawada | C6: https://remaxforge.com/vijayawada/ | D6: REBUILD | E6: P1 | F6: Flange Supplier in Vijayawada | Flanges Manufacturer | G6: =LEN(F6) -> 52 | H6: =IF(G6=0,"MISSING",IF(G6>60,"TOO LONG",IF(G6<30,"TOO SHORT","OK"))) -> OK | I6: Flanges for Vijayawada power stations, Kondapalli industry and Amaravati water and building works. ASME, EN and IS drilling. Written quotes by email. | J6: =LEN(I6) -> 149 | K6: =IF(J6=0,"MISSING",IF(J6>160,"TOO LONG",IF(J6<120,"SHORT","OK"))) -> OK | L6: Flange Supplier in Vijayawada & the Amaravati Capital Region | M6: Flanges manufacturer in Mumbai supplying power, industrial and capital-region projects around Vijayawada. | N6: 1100 | O6: =SUMIFS('8. City Content (Paste)'!$H$5:$H$400,'8. City Content (Paste)'!$A$5:$A$400,$A6)+SUMIFS('8b. Page Tables (Paste)'!$H$5:$H$300,'8b. Page Tables (Paste)'!$A$5:$A$300,$A6)+SUMIFS('9. FAQs (Paste)'!$F$5:$F$200,'9. FAQs (Paste)'!$A$5:$A$200,$A6) -> 1280 | P6: =IF(O6>=N6,"OK","BELOW FLOOR") -> OK | Q6: =COUNTIFS('8. City Content (Paste)'!$A$5:$A$400,$A6,'8. City Content (Paste)'!$I$5:$I$400,"<>Ready")+COUNTIFS('8b. Page Tables (Paste)'!$A$5:$A$300,$A6,'8b. Page Tables (Paste)'!$I$5:$I$300,"<>Ready")+COUNTIFS('9. FAQs (Paste)'!$A$5:$A$200,$A6,'9. FAQs (Paste)'!$G$5:$G$200,"<>Ready") -> 17 | R6: >= 65% unique 5-word shingles; max similarity to any other city page <= 0.25 | S6: Flange supply across Andhra Pradesh → /market-area/andhra-pradesh/ Guntur → /guntur/ Pipe flanges guide → /blogs/pipe-flanges-guide/ Kurnool (large-bore water projects) → /kurnool/ + 7 product-type links (tab 8b) | T6: AP hub; /guntur/ and /kurnool/ related links | U6: P05, P06, P12 | V6: V2 | W6: WebPage, BreadcrumbList, Service, FAQPage (+ sitewide Organization, WebSite, Person) | X6: Home › Areas We Supply › Andhra Pradesh › Vijayawada | Y6: index, follow | Z6: =IF(AND(H6="OK",K6="OK",P6="OK",Q6=0),"READY","NOT READY") -> NOT READY
A7: guntur | B7: Guntur | C7: https://remaxforge.com/guntur/ | D7: REBUILD | E7: P2 | F7: Flange Supplier in Guntur | Flanges Manufacturer | G7: =LEN(F7) -> 48 | H7: =IF(G7=0,"MISSING",IF(G7>60,"TOO LONG",IF(G7<30,"TOO SHORT","OK"))) -> OK | I7: Steel flanges for Guntur cold storages, ammonia refrigeration, mill boilers and capital-region projects. A105, LF2 and SS grades. Quotes by email. | J7: =LEN(I7) -> 146 | K7: =IF(J7=0,"MISSING",IF(J7>160,"TOO LONG",IF(J7<120,"SHORT","OK"))) -> OK | L7: Flange Supplier in Guntur | M7: Flanges manufacturer in Mumbai supplying cold chain, agro-processing and capital-region projects in Guntur district. | N7: 1050 | O7: =SUMIFS('8. City Content (Paste)'!$H$5:$H$400,'8. City Content (Paste)'!$A$5:$A$400,$A7)+SUMIFS('8b. Page Tables (Paste)'!$H$5:$H$300,'8b. Page Tables (Paste)'!$A$5:$A$300,$A7)+SUMIFS('9. FAQs (Paste)'!$F$5:$F$200,'9. FAQs (Paste)'!$A$5:$A$200,$A7) -> 1217 | P7: =IF(O7>=N7,"OK","BELOW FLOOR") -> OK | Q7: =COUNTIFS('8. City Content (Paste)'!$A$5:$A$400,$A7,'8. City Content (Paste)'!$I$5:$I$400,"<>Ready")+COUNTIFS('8b. Page Tables (Paste)'!$A$5:$A$300,$A7,'8b. Page Tables (Paste)'!$I$5:$I$300,"<>Ready")+COUNTIFS('9. FAQs (Paste)'!$A$5:$A$200,$A7,'9. FAQs (Paste)'!$G$5:$G$200,"<>Ready") -> 17 | R7: >= 65% unique 5-word shingles; max similarity to any other city page <= 0.25 | S7: Flange supply across Andhra Pradesh → /market-area/andhra-pradesh/ Vijayawada & Amaravati → /vijayawada/ Low-temperature flanges → /products/flanges/high-temperature-cryogenic-flange/ + 7 product-type links (tab 8b) | T7: AP hub; /vijayawada/ related links | U7: P01, P08, P11 | V7: V1 (reuse) | W7: WebPage, BreadcrumbList, Service, FAQPage (+ sitewide Organization, WebSite, Person) | X7: Home › Areas We Supply › Andhra Pradesh › Guntur | Y7: index, follow | Z7: =IF(AND(H7="OK",K7="OK",P7="OK",Q7=0),"READY","NOT READY") -> NOT READY
A8: nellore | B8: Nellore | C8: https://remaxforge.com/nellore/ | D8: REBUILD | E8: P1 | F8: Flange Supplier in Nellore | Flanges Manufacturer | G8: =LEN(F8) -> 49 | H8: =IF(G8=0,"MISSING",IF(G8>60,"TOO LONG",IF(G8<30,"TOO SHORT","OK"))) -> OK | I8: Flanges for Nellore power plants, Krishnapatnam port, seafood processors and the Ramayapatnam refinery supply chain. NACE, LF2 and alloy grades. | J8: =LEN(I8) -> 144 | K8: =IF(J8=0,"MISSING",IF(J8>160,"TOO LONG",IF(J8<120,"SHORT","OK"))) -> OK | L8: Flange Supplier in Nellore, Krishnapatnam & Ramayapatnam | M8: Flanges manufacturer in Mumbai supplying Nellore's power, port, seafood and refinery-project buyers. | N8: 1050 | O8: =SUMIFS('8. City Content (Paste)'!$H$5:$H$400,'8. City Content (Paste)'!$A$5:$A$400,$A8)+SUMIFS('8b. Page Tables (Paste)'!$H$5:$H$300,'8b. Page Tables (Paste)'!$A$5:$A$300,$A8)+SUMIFS('9. FAQs (Paste)'!$F$5:$F$200,'9. FAQs (Paste)'!$A$5:$A$200,$A8) -> 1230 | P8: =IF(O8>=N8,"OK","BELOW FLOOR") -> OK | Q8: =COUNTIFS('8. City Content (Paste)'!$A$5:$A$400,$A8,'8. City Content (Paste)'!$I$5:$I$400,"<>Ready")+COUNTIFS('8b. Page Tables (Paste)'!$A$5:$A$300,$A8,'8b. Page Tables (Paste)'!$I$5:$I$300,"<>Ready")+COUNTIFS('9. FAQs (Paste)'!$A$5:$A$200,$A8,'9. FAQs (Paste)'!$G$5:$G$200,"<>Ready") -> 17 | R8: >= 65% unique 5-word shingles; max similarity to any other city page <= 0.25 | S8: Flange supply across Andhra Pradesh → /market-area/andhra-pradesh/ Visakhapatnam → /visakhapatnam/ Sour-service NACE flanges → /products/flanges/sour-service-nace-flange/ Low-temperature flanges → /products/flanges/high-temperature-cryogenic-flange/ Flanges for oil & gas → /industries/oil-and-gas/ + 7 product-type links (tab 8b) | T8: AP hub; /visakhapatnam/ related links; /industries/oil-and-gas/ (optional) | U8: P07, P09, P10 | V8: V3 | W8: WebPage, BreadcrumbList, Service, FAQPage (+ sitewide Organization, WebSite, Person) | X8: Home › Areas We Supply › Andhra Pradesh › Nellore | Y8: index, follow | Z8: =IF(AND(H8="OK",K8="OK",P8="OK",Q8=0),"READY","NOT READY") -> NOT READY
A9: kurnool | B9: Kurnool | C9: https://remaxforge.com/kurnool/ | D9: REBUILD | E9: P2 | F9: Flange Supplier in Kurnool | Flanges Manufacturer | G9: =LEN(F9) -> 49 | H9: =IF(G9=0,"MISSING",IF(G9>60,"TOO LONG",IF(G9<30,"TOO SHORT","OK"))) -> OK | I9: Flanges for Kurnool pumped storage, lift irrigation, solar parks and cement plants. Large-bore, AWWA, EN and IS drilling. Written quotes by email. | J9: =LEN(I9) -> 146 | K9: =IF(J9=0,"MISSING",IF(J9>160,"TOO LONG",IF(J9<120,"SHORT","OK"))) -> OK | L9: Flange Supplier in Kurnool | M9: Flanges manufacturer in Mumbai supplying pumped-storage, irrigation, renewable and industrial projects around Kurnool. | N9: 1000 | O9: =SUMIFS('8. City Content (Paste)'!$H$5:$H$400,'8. City Content (Paste)'!$A$5:$A$400,$A9)+SUMIFS('8b. Page Tables (Paste)'!$H$5:$H$300,'8b. Page Tables (Paste)'!$A$5:$A$300,$A9)+SUMIFS('9. FAQs (Paste)'!$F$5:$F$200,'9. FAQs (Paste)'!$A$5:$A$200,$A9) -> 1196 | P9: =IF(O9>=N9,"OK","BELOW FLOOR") -> OK | Q9: =COUNTIFS('8. City Content (Paste)'!$A$5:$A$400,$A9,'8. City Content (Paste)'!$I$5:$I$400,"<>Ready")+COUNTIFS('8b. Page Tables (Paste)'!$A$5:$A$300,$A9,'8b. Page Tables (Paste)'!$I$5:$I$300,"<>Ready")+COUNTIFS('9. FAQs (Paste)'!$A$5:$A$200,$A9,'9. FAQs (Paste)'!$G$5:$G$200,"<>Ready") -> 17 | R9: >= 65% unique 5-word shingles; max similarity to any other city page <= 0.25 | S9: Flange supply across Andhra Pradesh → /market-area/andhra-pradesh/ Pipe flanges guide → /blogs/pipe-flanges-guide/ Vijayawada (Class 150 vs PN16 drilling) → /vijayawada/ + 7 product-type links (tab 8b) | T9: AP hub; /vijayawada/ related links | U9: P12, P06, P13 | V9: V4 | W9: WebPage, BreadcrumbList, Service, FAQPage (+ sitewide Organization, WebSite, Person) | X9: Home › Areas We Supply › Andhra Pradesh › Kurnool | Y9: index, follow | Z9: =IF(AND(H9="OK",K9="OK",P9="OK",Q9=0),"READY","NOT READY") -> NOT READY
A10: itanagar | B10: Itanagar & Naharlagun | C10: https://remaxforge.com/itanagar/ | D10: REBUILD + ABSORB NAHARLAGUN | E10: P3 | F10: Flange Supplier in Itanagar & Naharlagun | Manufacturer | G10: =LEN(F10) -> 55 | H10: =IF(G10=0,"MISSING",IF(G10>60,"TOO LONG",IF(G10<30,"TOO SHORT","OK"))) -> OK | I10: Flanges for water-supply, hospital, building and hydro projects in Itanagar and Naharlagun. Shipped from Mumbai via Guwahati. Written quotes by email. | J10: =LEN(I10) -> 150 | K10: =IF(J10=0,"MISSING",IF(J10>160,"TOO LONG",IF(J10<120,"SHORT","OK"))) -> OK | L10: Flange Supplier in Itanagar & Naharlagun (Capital Region) | M10: Flanges manufacturer in Mumbai supplying water-supply, building and hydropower work in the Itanagar capital region. | N10: 900 | O10: =SUMIFS('8. City Content (Paste)'!$H$5:$H$400,'8. City Content (Paste)'!$A$5:$A$400,$A10)+SUMIFS('8b. Page Tables (Paste)'!$H$5:$H$300,'8b. Page Tables (Paste)'!$A$5:$A$300,$A10)+SUMIFS('9. FAQs (Paste)'!$F$5:$F$200,'9. FAQs (Paste)'!$A$5:$A$200,$A10) -> 1053 | P10: =IF(O10>=N10,"OK","BELOW FLOOR") -> OK | Q10: =COUNTIFS('8. City Content (Paste)'!$A$5:$A$400,$A10,'8. City Content (Paste)'!$I$5:$I$400,"<>Ready")+COUNTIFS('8b. Page Tables (Paste)'!$A$5:$A$300,$A10,'8b. Page Tables (Paste)'!$I$5:$I$300,"<>Ready")+COUNTIFS('9. FAQs (Paste)'!$A$5:$A$200,$A10,'9. FAQs (Paste)'!$G$5:$G$200,"<>Ready") -> 18 | R10: >= 65% unique 5-word shingles; max similarity to any other city page <= 0.25 | S10: Flange supply across Arunachal Pradesh → /market-area/arunachal-pradesh/ Pipe flanges guide → /blogs/pipe-flanges-guide/ + 7 product-type links (tab 8b) | T10: AR hub (Itanagar section + list) | U10: P13, P14, P11 | V10: V5 | W10: WebPage, BreadcrumbList, Service, FAQPage (+ sitewide Organization, WebSite, Person) | X10: Home › Areas We Supply › Arunachal Pradesh › Itanagar & Naharlagun | Y10: index, follow | Z10: =IF(AND(H10="OK",K10="OK",P10="OK",Q10=0),"READY","NOT READY") -> NOT READY
A11: ap_hub | B11: Andhra Pradesh hub | C11: https://remaxforge.com/market-area/andhra-pradesh/ | D11: NEW | E11: P1 | F11: Flange Supplier in Andhra Pradesh | Flanges Manufacturer | G11: =LEN(F11) -> 56 | H11: =IF(G11=0,"MISSING",IF(G11>60,"TOO LONG",IF(G11<30,"TOO SHORT","OK"))) -> OK | I11: Forged flanges across Andhra Pradesh: Vizag steel and refinery belt, Nellore ports, Amaravati works, Kurnool pumped storage. Written quotes by email. | J11: =LEN(I11) -> 149 | K11: =IF(J11=0,"MISSING",IF(J11>160,"TOO LONG",IF(J11<120,"SHORT","OK"))) -> OK | L11: Flanges Manufacturer & Supplier for Andhra Pradesh | M11: One Mumbai manufacturer supplying Andhra Pradesh's steel, refinery, power, port, water and capital-region projects. | N11: 550 | O11: =SUMIFS('8. City Content (Paste)'!$H$5:$H$400,'8. City Content (Paste)'!$A$5:$A$400,$A11)+SUMIFS('8b. Page Tables (Paste)'!$H$5:$H$300,'8b. Page Tables (Paste)'!$A$5:$A$300,$A11)+SUMIFS('9. FAQs (Paste)'!$F$5:$F$200,'9. FAQs (Paste)'!$A$5:$A$200,$A11) -> 881 | P11: =IF(O11>=N11,"OK","BELOW FLOOR") -> OK | Q11: =COUNTIFS('8. City Content (Paste)'!$A$5:$A$400,$A11,'8. City Content (Paste)'!$I$5:$I$400,"<>Ready")+COUNTIFS('8b. Page Tables (Paste)'!$A$5:$A$300,$A11,'8b. Page Tables (Paste)'!$I$5:$I$300,"<>Ready")+COUNTIFS('9. FAQs (Paste)'!$A$5:$A$200,$A11,'9. FAQs (Paste)'!$G$5:$G$200,"<>Ready") -> 7 | R11: Hub copy unique; city summaries must not repeat city-page sentences | S11: Visakhapatnam → /visakhapatnam/ Vijayawada → /vijayawada/ Guntur → /guntur/ Nellore → /nellore/ Kurnool → /kurnool/ All flange types → /products/flanges/ | T11: /market-area/ index; breadcrumb of all 5 AP city pages; body link from each AP city page | U11: P03, P11 | V11: V1 | W11: CollectionPage, BreadcrumbList, Service, FAQPage (+ sitewide Organization, WebSite, Person) | X11: Home › Areas We Supply › Andhra Pradesh | Y11: index, follow | Z11: =IF(AND(H11="OK",K11="OK",P11="OK",Q11=0),"READY","NOT READY") -> NOT READY
